
***************************************************************************
File "/Users/sb/git/nltk/nltk/test/align.doctest", line 14, in align.doctest
Failed example:
    comtrans.words('alignment-en-fr.txt')
Exception raised:
    Traceback (most recent call last):
      File "/opt/local/Library/Frameworks/Python.framework/Versions/2.6/lib/python2.6/doctest.py", line 1253, in __run
        compileflags, 1) in test.globs
      File "<doctest align.doctest[1]>", line 1, in <module>
        comtrans.words('alignment-en-fr.txt')
      File "/Users/sb/git/nltk/nltk/corpus/util.py", line 68, in __getattr__
        self.__load()
      File "/Users/sb/git/nltk/nltk/corpus/util.py", line 56, in __load
        except LookupError: raise e
    LookupError: 
    **********************************************************************
      Resource 'corpora/comtrans' not found.  Please use the NLTK
      Downloader to obtain the resource: >>> nltk.download().
      Searched in:
        - '/Users/sb/nltk_data'
        - '/usr/share/nltk_data'
        - '/usr/local/share/nltk_data'
        - '/usr/lib/nltk_data'
        - '/usr/local/lib/nltk_data'
    **********************************************************************

***************************************************************************
File "/Users/sb/git/nltk/nltk/test/align.doctest", line 16, in align.doctest
Failed example:
    als = comtrans.aligned_sents('alignment-en-fr.txt')[0]
Exception raised:
    Traceback (most recent call last):
      File "/opt/local/Library/Frameworks/Python.framework/Versions/2.6/lib/python2.6/doctest.py", line 1253, in __run
        compileflags, 1) in test.globs
      File "<doctest align.doctest[2]>", line 1, in <module>
        als = comtrans.aligned_sents('alignment-en-fr.txt')[0]
      File "/Users/sb/git/nltk/nltk/corpus/util.py", line 68, in __getattr__
        self.__load()
      File "/Users/sb/git/nltk/nltk/corpus/util.py", line 56, in __load
        except LookupError: raise e
    LookupError: 
    **********************************************************************
      Resource 'corpora/comtrans' not found.  Please use the NLTK
      Downloader to obtain the resource: >>> nltk.download().
      Searched in:
        - '/Users/sb/nltk_data'
        - '/usr/share/nltk_data'
        - '/usr/local/share/nltk_data'
        - '/usr/lib/nltk_data'
        - '/usr/local/lib/nltk_data'
    **********************************************************************

***************************************************************************
File "/Users/sb/git/nltk/nltk/test/align.doctest", line 17, in align.doctest
Failed example:
    als  # doctest: +NORMALIZE_WHITESPACE
Exception raised:
    Traceback (most recent call last):
      File "/opt/local/Library/Frameworks/Python.framework/Versions/2.6/lib/python2.6/doctest.py", line 1253, in __run
        compileflags, 1) in test.globs
      File "<doctest align.doctest[3]>", line 1, in <module>
        als  # doctest: +NORMALIZE_WHITESPACE
    NameError: name 'als' is not defined

***************************************************************************
File "/Users/sb/git/nltk/nltk/test/align.doctest", line 28, in align.doctest
Failed example:
    als.words
Exception raised:
    Traceback (most recent call last):
      File "/opt/local/Library/Frameworks/Python.framework/Versions/2.6/lib/python2.6/doctest.py", line 1253, in __run
        compileflags, 1) in test.globs
      File "<doctest align.doctest[4]>", line 1, in <module>
        als.words
    NameError: name 'als' is not defined

***************************************************************************
File "/Users/sb/git/nltk/nltk/test/align.doctest", line 30, in align.doctest
Failed example:
    als.mots
Exception raised:
    Traceback (most recent call last):
      File "/opt/local/Library/Frameworks/Python.framework/Versions/2.6/lib/python2.6/doctest.py", line 1253, in __run
        compileflags, 1) in test.globs
      File "<doctest align.doctest[5]>", line 1, in <module>
        als.mots
    NameError: name 'als' is not defined

***************************************************************************
File "/Users/sb/git/nltk/nltk/test/align.doctest", line 32, in align.doctest
Failed example:
    als.alignment
Exception raised:
    Traceback (most recent call last):
      File "/opt/local/Library/Frameworks/Python.framework/Versions/2.6/lib/python2.6/doctest.py", line 1253, in __run
        compileflags, 1) in test.globs
      File "<doctest align.doctest[6]>", line 1, in <module>
        als.alignment
    NameError: name 'als' is not defined

***************************************************************************
File "/Users/sb/git/nltk/nltk/test/align.doctest", line 39, in align.doctest
Failed example:
    als.invert() # doctest: +NORMALIZE_WHITESPACE
Exception raised:
    Traceback (most recent call last):
      File "/opt/local/Library/Frameworks/Python.framework/Versions/2.6/lib/python2.6/doctest.py", line 1253, in __run
        compileflags, 1) in test.globs
      File "<doctest align.doctest[7]>", line 1, in <module>
        als.invert() # doctest: +NORMALIZE_WHITESPACE
    NameError: name 'als' is not defined

***************************************************************************
File "/Users/sb/git/nltk/nltk/test/align.doctest", line 49, in align.doctest
Failed example:
    als.alignment = align.Alignment([(0, 0), (1, 4), (2, 1), (3, 3)])
Expected:
    Traceback (most recent call last):
        ...
    IndexError: Alignment is outside boundary of mots
Got:
    Traceback (most recent call last):
      File "/opt/local/Library/Frameworks/Python.framework/Versions/2.6/lib/python2.6/doctest.py", line 1253, in __run
        compileflags, 1) in test.globs
      File "<doctest align.doctest[9]>", line 1, in <module>
        als.alignment = align.Alignment([(0, 0), (1, 4), (2, 1), (3, 3)])
    NameError: name 'als' is not defined

***************************************************************************
File "/Users/sb/git/nltk/nltk/test/align.doctest", line 53, in align.doctest
Failed example:
    als.alignment = align.Alignment([(-1, 0), (1, 2), (2, 1), (3, 3)])
Expected:
    Traceback (most recent call last):
        ...
    IndexError: Alignment is outside boundary of words
Got:
    Traceback (most recent call last):
      File "/opt/local/Library/Frameworks/Python.framework/Versions/2.6/lib/python2.6/doctest.py", line 1253, in __run
        compileflags, 1) in test.globs
      File "<doctest align.doctest[10]>", line 1, in <module>
        als.alignment = align.Alignment([(-1, 0), (1, 2), (2, 1), (3, 3)])
    NameError: name 'als' is not defined

***************************************************************************
File "/Users/sb/git/nltk/nltk/test/align.doctest", line 57, in align.doctest
Failed example:
    als.alignment
Exception raised:
    Traceback (most recent call last):
      File "/opt/local/Library/Frameworks/Python.framework/Versions/2.6/lib/python2.6/doctest.py", line 1253, in __run
        compileflags, 1) in test.globs
      File "<doctest align.doctest[11]>", line 1, in <module>
        als.alignment
    NameError: name 'als' is not defined

***************************************************************************
File "/Users/sb/git/nltk/nltk/test/align.doctest", line 59, in align.doctest
Failed example:
    als.alignment = align.Alignment([(1, 3), (3, 2), (0, 1), (2, 0)])
Exception raised:
    Traceback (most recent call last):
      File "/opt/local/Library/Frameworks/Python.framework/Versions/2.6/lib/python2.6/doctest.py", line 1253, in __run
        compileflags, 1) in test.globs
      File "<doctest align.doctest[12]>", line 1, in <module>
        als.alignment = align.Alignment([(1, 3), (3, 2), (0, 1), (2, 0)])
    NameError: name 'als' is not defined

***************************************************************************
File "/Users/sb/git/nltk/nltk/test/align.doctest", line 60, in align.doctest
Failed example:
    als.alignment
Exception raised:
    Traceback (most recent call last):
      File "/opt/local/Library/Frameworks/Python.framework/Versions/2.6/lib/python2.6/doctest.py", line 1253, in __run
        compileflags, 1) in test.globs
      File "<doctest align.doctest[13]>", line 1, in <module>
        als.alignment
    NameError: name 'als' is not defined

***************************************************************************
File "/Users/sb/git/nltk/nltk/test/align.doctest", line 67, in align.doctest
Failed example:
    als.alignment = [(0, 0), (1, 1), (2, 2, "boat"), (3, 3, False, (1,2))]
Exception raised:
    Traceback (most recent call last):
      File "/opt/local/Library/Frameworks/Python.framework/Versions/2.6/lib/python2.6/doctest.py", line 1253, in __run
        compileflags, 1) in test.globs
      File "<doctest align.doctest[14]>", line 1, in <module>
        als.alignment = [(0, 0), (1, 1), (2, 2, "boat"), (3, 3, False, (1,2))]
    NameError: name 'als' is not defined

***************************************************************************
File "/Users/sb/git/nltk/nltk/test/align.doctest", line 68, in align.doctest
Failed example:
    als.alignment
Exception raised:
    Traceback (most recent call last):
      File "/opt/local/Library/Frameworks/Python.framework/Versions/2.6/lib/python2.6/doctest.py", line 1253, in __run
        compileflags, 1) in test.globs
      File "<doctest align.doctest[15]>", line 1, in <module>
        als.alignment
    NameError: name 'als' is not defined

***************************************************************************
File "/Users/sb/git/nltk/nltk/test/align.doctest", line 70, in align.doctest
Failed example:
    als.alignment = ((0, 0), (1, 1), (2, 2), (3, 3))
Exception raised:
    Traceback (most recent call last):
      File "/opt/local/Library/Frameworks/Python.framework/Versions/2.6/lib/python2.6/doctest.py", line 1253, in __run
        compileflags, 1) in test.globs
      File "<doctest align.doctest[16]>", line 1, in <module>
        als.alignment = ((0, 0), (1, 1), (2, 2), (3, 3))
    NameError: name 'als' is not defined

***************************************************************************
File "/Users/sb/git/nltk/nltk/test/align.doctest", line 71, in align.doctest
Failed example:
    als.alignment
Exception raised:
    Traceback (most recent call last):
      File "/opt/local/Library/Frameworks/Python.framework/Versions/2.6/lib/python2.6/doctest.py", line 1253, in __run
        compileflags, 1) in test.globs
      File "<doctest align.doctest[17]>", line 1, in <module>
        als.alignment
    NameError: name 'als' is not defined

***************************************************************************
File "/Users/sb/git/nltk/nltk/test/align.doctest", line 111, in align.doctest
Failed example:
    em_ibm1.aligned() # doctest: +NORMALIZE_WHITESPACE
Exception raised:
    Traceback (most recent call last):
      File "/opt/local/Library/Frameworks/Python.framework/Versions/2.6/lib/python2.6/doctest.py", line 1253, in __run
        compileflags, 1) in test.globs
      File "<doctest align.doctest[31]>", line 1, in <module>
        em_ibm1.aligned() # doctest: +NORMALIZE_WHITESPACE
      File "/Users/sb/git/nltk/nltk/align.py", line 353, in aligned
        if self.probablities is None:
    AttributeError: 'EMIBMModel1' object has no attribute 'probablities'

***************************************************************************
File "/Users/sb/git/nltk/nltk/test/align.doctest", line 153, in align.doctest
Failed example:
    print als.precision(set())
Exception raised:
    Traceback (most recent call last):
      File "/opt/local/Library/Frameworks/Python.framework/Versions/2.6/lib/python2.6/doctest.py", line 1253, in __run
        compileflags, 1) in test.globs
      File "<doctest align.doctest[33]>", line 1, in <module>
        print als.precision(set())
    NameError: name 'als' is not defined

***************************************************************************
File "/Users/sb/git/nltk/nltk/test/align.doctest", line 155, in align.doctest
Failed example:
    print als.precision([(0,0), (1,1), (2,2), (3,3)])
Exception raised:
    Traceback (most recent call last):
      File "/opt/local/Library/Frameworks/Python.framework/Versions/2.6/lib/python2.6/doctest.py", line 1253, in __run
        compileflags, 1) in test.globs
      File "<doctest align.doctest[34]>", line 1, in <module>
        print als.precision([(0,0), (1,1), (2,2), (3,3)])
    NameError: name 'als' is not defined

***************************************************************************
File "/Users/sb/git/nltk/nltk/test/align.doctest", line 157, in align.doctest
Failed example:
    print als.precision([(0,0), (3,3)])
Exception raised:
    Traceback (most recent call last):
      File "/opt/local/Library/Frameworks/Python.framework/Versions/2.6/lib/python2.6/doctest.py", line 1253, in __run
        compileflags, 1) in test.globs
      File "<doctest align.doctest[35]>", line 1, in <module>
        print als.precision([(0,0), (3,3)])
    NameError: name 'als' is not defined

***************************************************************************
File "/Users/sb/git/nltk/nltk/test/align.doctest", line 159, in align.doctest
Failed example:
    print als.precision([(0,0), (1,1), (2,2), (3,3), (1,2), (2,1)])
Exception raised:
    Traceback (most recent call last):
      File "/opt/local/Library/Frameworks/Python.framework/Versions/2.6/lib/python2.6/doctest.py", line 1253, in __run
        compileflags, 1) in test.globs
      File "<doctest align.doctest[36]>", line 1, in <module>
        print als.precision([(0,0), (1,1), (2,2), (3,3), (1,2), (2,1)])
    NameError: name 'als' is not defined

***************************************************************************
File "/Users/sb/git/nltk/nltk/test/align.doctest", line 161, in align.doctest
Failed example:
    print my_als.precision(als)
Exception raised:
    Traceback (most recent call last):
      File "/opt/local/Library/Frameworks/Python.framework/Versions/2.6/lib/python2.6/doctest.py", line 1253, in __run
        compileflags, 1) in test.globs
      File "<doctest align.doctest[37]>", line 1, in <module>
        print my_als.precision(als)
    NameError: name 'als' is not defined

***************************************************************************
File "/Users/sb/git/nltk/nltk/test/align.doctest", line 182, in align.doctest
Failed example:
    print als.recall(set())
Exception raised:
    Traceback (most recent call last):
      File "/opt/local/Library/Frameworks/Python.framework/Versions/2.6/lib/python2.6/doctest.py", line 1253, in __run
        compileflags, 1) in test.globs
      File "<doctest align.doctest[38]>", line 1, in <module>
        print als.recall(set())
    NameError: name 'als' is not defined

***************************************************************************
File "/Users/sb/git/nltk/nltk/test/align.doctest", line 184, in align.doctest
Failed example:
    print als.recall([(0,0), (1,1), (2,2), (3,3)])
Exception raised:
    Traceback (most recent call last):
      File "/opt/local/Library/Frameworks/Python.framework/Versions/2.6/lib/python2.6/doctest.py", line 1253, in __run
        compileflags, 1) in test.globs
      File "<doctest align.doctest[39]>", line 1, in <module>
        print als.recall([(0,0), (1,1), (2,2), (3,3)])
    NameError: name 'als' is not defined

***************************************************************************
File "/Users/sb/git/nltk/nltk/test/align.doctest", line 186, in align.doctest
Failed example:
    print als.recall([(0,0), (3,3)])
Exception raised:
    Traceback (most recent call last):
      File "/opt/local/Library/Frameworks/Python.framework/Versions/2.6/lib/python2.6/doctest.py", line 1253, in __run
        compileflags, 1) in test.globs
      File "<doctest align.doctest[40]>", line 1, in <module>
        print als.recall([(0,0), (3,3)])
    NameError: name 'als' is not defined

***************************************************************************
File "/Users/sb/git/nltk/nltk/test/align.doctest", line 188, in align.doctest
Failed example:
    print als.recall([(0,0), (1,1), (2,2), (3,3), (1,2), (2,1)])
Exception raised:
    Traceback (most recent call last):
      File "/opt/local/Library/Frameworks/Python.framework/Versions/2.6/lib/python2.6/doctest.py", line 1253, in __run
        compileflags, 1) in test.globs
      File "<doctest align.doctest[41]>", line 1, in <module>
        print als.recall([(0,0), (1,1), (2,2), (3,3), (1,2), (2,1)])
    NameError: name 'als' is not defined

***************************************************************************
File "/Users/sb/git/nltk/nltk/test/align.doctest", line 190, in align.doctest
Failed example:
    print my_als.recall(als)
Exception raised:
    Traceback (most recent call last):
      File "/opt/local/Library/Frameworks/Python.framework/Versions/2.6/lib/python2.6/doctest.py", line 1253, in __run
        compileflags, 1) in test.globs
      File "<doctest align.doctest[42]>", line 1, in <module>
        print my_als.recall(als)
    NameError: name 'als' is not defined

***************************************************************************
File "/Users/sb/git/nltk/nltk/test/align.doctest", line 215, in align.doctest
Failed example:
    print als.alignment_error_rate(set())
Exception raised:
    Traceback (most recent call last):
      File "/opt/local/Library/Frameworks/Python.framework/Versions/2.6/lib/python2.6/doctest.py", line 1253, in __run
        compileflags, 1) in test.globs
      File "<doctest align.doctest[43]>", line 1, in <module>
        print als.alignment_error_rate(set())
    NameError: name 'als' is not defined

***************************************************************************
File "/Users/sb/git/nltk/nltk/test/align.doctest", line 217, in align.doctest
Failed example:
    print als.alignment_error_rate([(0,0), (1,1), (2,2), (3,3)])
Exception raised:
    Traceback (most recent call last):
      File "/opt/local/Library/Frameworks/Python.framework/Versions/2.6/lib/python2.6/doctest.py", line 1253, in __run
        compileflags, 1) in test.globs
      File "<doctest align.doctest[44]>", line 1, in <module>
        print als.alignment_error_rate([(0,0), (1,1), (2,2), (3,3)])
    NameError: name 'als' is not defined

***************************************************************************
File "/Users/sb/git/nltk/nltk/test/align.doctest", line 219, in align.doctest
Failed example:
    print my_als.alignment_error_rate(als)
Exception raised:
    Traceback (most recent call last):
      File "/opt/local/Library/Frameworks/Python.framework/Versions/2.6/lib/python2.6/doctest.py", line 1253, in __run
        compileflags, 1) in test.globs
      File "<doctest align.doctest[45]>", line 1, in <module>
        print my_als.alignment_error_rate(als)
    NameError: name 'als' is not defined

***************************************************************************
File "/Users/sb/git/nltk/nltk/test/align.doctest", line 221, in align.doctest
Failed example:
    print my_als.alignment_error_rate(als,
        als.alignment | set([(1,2), (2,1)]))
Exception raised:
    Traceback (most recent call last):
      File "/opt/local/Library/Frameworks/Python.framework/Versions/2.6/lib/python2.6/doctest.py", line 1253, in __run
        compileflags, 1) in test.globs
      File "<doctest align.doctest[46]>", line 1, in <module>
        print my_als.alignment_error_rate(als,
    NameError: name 'als' is not defined
.